Workbook

Sheet Didascalie
A1: DIDASCALIE DEL PORTFOLIO
A2: Modifica la colonna D. Per applicare le modifiche al sito, salva il file e avvia python3 aggiorna_didascalie.py dal Terminale nella cartella del sito.
A3: Anteprima | B3: Progetto | C3: Immagini associate | D3: Didascalia modificabile
B4: Camouflage | C4: Camouflage_1.jpeg, Camouflage_2.jpeg, Camouflage_3.jpeg, Camouflage_4.jpeg, Camouflage_6.jpeg, Camouflage_8.jpeg, Camouflage_9.jpeg, Camouflage_10.jpeg | D4: Camouflage. An Act of conformity and resistance, 2024-5. Research, writing, graphic and book design.
B5: DDDD | C5: DDDD_1.jpeg | D5: Editorial and Production Assistant for Daily Dense Dance Desiderio (DDDD) by Riccardo Benassi, 2021
B6: DDDD Book | C6: DDDDBook_1.jpeg, DDDDBook_2.jpeg | D6: Editorial Coordinator and Contributing Author for Daily Dense Dance Desiderio (DDDD) by Riccardo Benassi, 2024
B7: Danceflorensick | C7: Danceflosensick_1.jpeg | D7: Camera and Production Assistant for Danceflorensick by Riccardo Benassi, 2022
B8: Deviante | C8: Deviante.jpg | D8: Magazine cover design for Deviante, 2024
B9: First Sight | C9: FirstSight_1.jpeg | D9: Photography and book design for First Sight, 2025
B10: Flash Art | C10: FlashArt_1.jpeg, FlashArt_2.jpeg | D10: Graphic design for Casa Flash Art by Chiara Belardi, 2023
B11: Frey Barth | C11: FreyBarth_1.jpeg, FreyBarth_2.jpeg | D11: Freelance Junior Graphic Designer for Carina Frey and Stefanie Barth, 2025-6
B12: Hyper Inertia | C12: HyperInertia_1.jpeg, HyperInertia_2.jpeg, HyperInertia_3.jpeg | D12: Editorial Art Direction and Graphic Design with Francesca Barizza for Deviante, 2024
B13: KV ROES | C13: KvRoes_3.jpeg, KvRoes_4.jpeg, KvRoes_5.jpeg, KvRoes_7.jpeg, KvRoes_8.jpeg, KvRoes_9.jpeg | D13: Head of Communication and Graphic Design for Kv Roes, 2024 ongoing
B14: Maquette | C14: Maquette_.jpeg, Maquette_1.jpeg, Maquette_10.jpeg, Maquette_11.jpeg, Maquette_2.jpeg, Maquette_3.jpeg, Maquette_4.jpeg, Maquette_5.jpeg, Maquette_6.jpeg, Maquette_8.jpeg, Maquette_9.jpeg | D14: Visual Identity and Art Direction for Maquette with Pepe Spike Studio, 2026
B15: Process | C15: Process_2.jpeg, Process_3.jpeg | D15: Pics from Design process
... B21: Y | C21: y_1.jpeg, y_2.jpeg | D21: Art direction and book design of Y, 2025

Sheet Immagini
A1: Anteprima | B1: Progetto | C1: File immagine | D1: Didascalia progetto
B2: Camouflage | C2: Camouflage_1.jpeg | D2: =Didascalie!D4 -> Camouflage. An Act of conformity and resistance, 2024-5. Research, writing, graphic and book design.
B3: Camouflage | C3: Camouflage_2.jpeg | D3: =Didascalie!D4 -> Camouflage. An Act of conformity and resistance, 2024-5. Research, writing, graphic and book design.
B4: Camouflage | C4: Camouflage_3.jpeg | D4: =Didascalie!D4 -> Camouflage. An Act of conformity and resistance, 2024-5. Research, writing, graphic and book design.
B5: Camouflage | C5: Camouflage_4.jpeg | D5: =Didascalie!D4 -> Camouflage. An Act of conformity and resistance, 2024-5. Research, writing, graphic and book design.
B6: Camouflage | C6: Camouflage_6.jpeg | D6: =Didascalie!D4 -> Camouflage. An Act of conformity and resistance, 2024-5. Research, writing, graphic and book design.
B7: Camouflage | C7: Camouflage_8.jpeg | D7: =Didascalie!D4 -> Camouflage. An Act of conformity and resistance, 2024-5. Research, writing, graphic and book design.
B8: Camouflage | C8: Camouflage_9.jpeg | D8: =Didascalie!D4 -> Camouflage. An Act of conformity and resistance, 2024-5. Research, writing, graphic and book design.
B9: Camouflage | C9: Camouflage_10.jpeg | D9: =Didascalie!D4 -> Camouflage. An Act of conformity and resistance, 2024-5. Research, writing, graphic and book design.
B10: DDDD | C10: DDDD_1.jpeg | D10: =Didascalie!D5 -> Editorial and Production Assistant for Daily Dense Dance Desiderio (DDDD) by Riccardo Benassi, 2021
B11: DDDD Book | C11: DDDDBook_1.jpeg | D11: =Didascalie!D6 -> Editorial Coordinator and Contributing Author for Daily Dense Dance Desiderio (DDDD) by Riccardo Benassi, 2024
B12: DDDD Book | C12: DDDDBook_2.jpeg | D12: =Didascalie!D6 -> Editorial Coordinator and Contributing Author for Daily Dense Dance Desiderio (DDDD) by Riccardo Benassi, 2024
B13: Danceflorensick | C13: Danceflosensick_1.jpeg | D13: =Didascalie!D7 -> Camera and Production Assistant for Danceflorensick by Riccardo Benassi, 2022
B14: Deviante | C14: Deviante.jpg | D14: =Didascalie!D8 -> Magazine cover design for Deviante, 2024
B15: First Sight | C15: FirstSight_1.jpeg | D15: =Didascalie!D9 -> Photography and book design for First Sight, 2025
B16: Flash Art | C16: FlashArt_1.jpeg | D16: =Didascalie!D10 -> Graphic design for Casa Flash Art by Chiara Belardi, 2023
B17: Flash Art | C17: FlashArt_2.jpeg | D17: =Didascalie!D10 -> Graphic design for Casa Flash Art by Chiara Belardi, 2023
B18: Frey Barth | C18: FreyBarth_1.jpeg | D18: =Didascalie!D11 -> Freelance Junior Graphic Designer for Carina Frey and Stefanie Barth, 2025-6
B19: Frey Barth | C19: FreyBarth_2.jpeg | D19: =Didascalie!D11 -> Freelance Junior Graphic Designer for Carina Frey and Stefanie Barth, 2025-6
B20: Hyper Inertia | C20: HyperInertia_1.jpeg | D20: =Didascalie!D12 -> Editorial Art Direction and Graphic Design with Francesca Barizza for Deviante, 2024
B21: Hyper Inertia | C21: HyperInertia_2.jpeg | D21: =Didascalie!D12 -> Editorial Art Direction and Graphic Design with Francesca Barizza for Deviante, 2024
B22: Hyper Inertia | C22: HyperInertia_3.jpeg | D22: =Didascalie!D12 -> Editorial Art Direction and Graphic Design with Francesca Barizza for Deviante, 2024
B23: KV ROES | C23: KvRoes_3.jpeg | D23: =Didascalie!D13 -> Head of Communication and Graphic Design for Kv Roes, 2024 ongoing
B24: KV ROES | C24: KvRoes_4.jpeg | D24: =Didascalie!D13 -> Head of Communication and Graphic Design for Kv Roes, 2024 ongoing
B25: KV ROES | C25: KvRoes_5.jpeg | D25: =Didascalie!D13 -> Head of Communication and Graphic Design for Kv Roes, 2024 ongoing
B26: KV ROES | C26: KvRoes_7.jpeg | D26: =Didascalie!D13 -> Head of Communication and Graphic Design for Kv Roes, 2024 ongoing
B27: KV ROES | C27: KvRoes_8.jpeg | D27: =Didascalie!D13 -> Head of Communication and Graphic Design for Kv Roes, 2024 ongoing
B28: KV ROES | C28: KvRoes_9.jpeg | D28: =Didascalie!D13 -> Head of Communication and Graphic Design for Kv Roes, 2024 ongoing
B29: Maquette | C29: Maquette_.jpeg | D29: =Didascalie!D14 -> Visual Identity and Art Direction for Maquette with Pepe Spike Studio, 2026
B30: Maquette | C30: Maquette_1.jpeg | D30: =Didascalie!D14 -> Visual Identity and Art Direction for Maquette with Pepe Spike Studio, 2026
B31: Maquette | C31: Maquette_10.jpeg | D31: =Didascalie!D14 -> Visual Identity and Art Direction for Maquette with Pepe Spike Studio, 2026
B32: Maquette | C32: Maquette_11.jpeg | D32: =Didascalie!D14 -> Visual Identity and Art Direction for Maquette with Pepe Spike Studio, 2026
B33: Maquette | C33: Maquette_2.jpeg | D33: =Didascalie!D14 -> Visual Identity and Art Direction for Maquette with Pepe Spike Studio, 2026
B34: Maquette | C34: Maquette_3.jpeg | D34: =Didascalie!D14 -> Visual Identity and Art Direction for Maquette with Pepe Spike Studio, 2026
B35: Maquette | C35: Maquette_4.jpeg | D35: =Didascalie!D14 -> Visual Identity and Art Direction for Maquette with Pepe Spike Studio, 2026
B36: Maquette | C36: Maquette_5.jpeg | D36: =Didascalie!D14 -> Visual Identity and Art Direction for Maquette with Pepe Spike Studio, 2026
B37: Maquette | C37: Maquette_6.jpeg | D37: =Didascalie!D14 -> Visual Identity and Art Direction for Maquette with Pepe Spike Studio, 2026
B38: Maquette | C38: Maquette_8.jpeg | D38: =Didascalie!D14 -> Visual Identity and Art Direction for Maquette with Pepe Spike Studio, 2026
B39: Maquette | C39: Maquette_9.jpeg | D39: =Didascalie!D14 -> Visual Identity and Art Direction for Maquette with Pepe Spike Studio, 2026
B40: Process | C40: Process_2.jpeg | D40: =Didascalie!D15 -> Pics from Design process
...
